2021-06-21 15:54:23,514 - [test_login07.py -->line:52] - INFO:测试编号1,测试用例的标题为:登录成功,执行成功！
2021-06-21 15:54:23,576 - [test_login07.py -->line:52] - INFO:测试编号2,测试用例的标题为:用户名为空,执行成功！
2021-06-21 15:54:23,623 - [test_login07.py -->line:52] - INFO:测试编号3,测试用例的标题为:用户名或密码错误,执行成功！
2021-06-21 15:54:23,671 - [test_login07.py -->line:52] - INFO:测试编号4,测试用例的标题为:密码为空,执行成功！
2021-06-21 15:54:23,734 - [test_login07.py -->line:52] - INFO:测试编号5,测试用例的标题为:用户名或密码错误,执行成功！
2021-06-21 15:54:23,803 - [test_regist07.py -->line:49] - INFO:测试编号1,测试用例标题正确流程,执行成功
2021-06-21 15:54:23,850 - [test_regist07.py -->line:49] - INFO:测试编号2,测试用例标题用户名为空,执行成功
2021-06-21 15:54:23,897 - [test_regist07.py -->line:49] - INFO:测试编号3,测试用例标题密码为空,执行成功
2021-06-21 15:54:23,960 - [test_regist07.py -->line:49] - INFO:测试编号4,测试用例标题确认密码不能为空,执行成功
2021-06-21 15:54:24,007 - [test_regist07.py -->line:49] - INFO:测试编号5,测试用例标题用户名已经存在,执行成功
2021-06-21 15:54:24,053 - [test_regist07.py -->line:49] - INFO:测试编号6,测试用例标题密码和确认密码不一致,执行成功
2021-06-21 15:54:24,085 - [test_regist07.py -->line:49] - INFO:测试编号7,测试用例标题用户名小于6位,执行成功
2021-06-21 15:54:24,116 - [test_regist07.py -->line:49] - INFO:测试编号8,测试用例标题用户名大于18位,执行成功
2021-06-21 15:54:24,147 - [test_regist07.py -->line:49] - INFO:测试编号9,测试用例标题密码小于6位,执行成功
2021-06-21 15:54:24,179 - [test_regist07.py -->line:49] - INFO:测试编号10,测试用例标题密码大于18位,执行成功
2021-06-21 15:54:24,211 - [test_regist07.py -->line:49] - INFO:测试编号11,测试用例标题密码17位,执行成功
2021-06-21 15:54:24,242 - [test_regist07.py -->line:44] - ERROR:测试编号12,测试用例标题邮箱不能为空,执行失败,实际结果：{'code': 1006, 'msg': '邮箱不能为空'}
2021-06-21 15:54:24,242 - [test_regist07.py -->line:45] - ERROR:{'code': 10066, 'msg': '邮箱不能为空'} != {'code': 1006, 'msg': '邮箱不能为空'}
- {'code': 10066, 'msg': '邮箱不能为空'}
?              -

+ {'code': 1006, 'msg': '邮箱不能为空'}
Traceback (most recent call last):
  File "D:\Tools\PythonWorkSpace\autotest02\testcases\test_regist07.py", line 40, in test_register
    self.assertEqual(eval(case.expect), res_body)
  File "D:\Tools\Python\lib\unittest\case.py", line 839, in assertEqual
    assertion_func(first, second, msg=msg)
  File "D:\Tools\Python\lib\unittest\case.py", line 1138, in assertDictEqual
    self.fail(self._formatMessage(msg, standardMsg))
  File "D:\Tools\Python\lib\unittest\case.py", line 680, in fail
    raise self.failureException(msg)
AssertionError: {'code': 10066, 'msg': '邮箱不能为空'} != {'code': 1006, 'msg': '邮箱不能为空'}
- {'code': 10066, 'msg': '邮箱不能为空'}
?              -

+ {'code': 1006, 'msg': '邮箱不能为空'}
2021-06-21 16:51:50,724 - [test_login07.py -->line:52] - INFO:测试编号1,测试用例的标题为:登录成功,执行成功！
2021-06-21 16:51:50,771 - [test_login07.py -->line:52] - INFO:测试编号2,测试用例的标题为:用户名为空,执行成功！
2021-06-21 16:51:50,833 - [test_login07.py -->line:52] - INFO:测试编号3,测试用例的标题为:用户名或密码错误,执行成功！
2021-06-21 16:51:50,880 - [test_login07.py -->line:52] - INFO:测试编号4,测试用例的标题为:密码为空,执行成功！
2021-06-21 16:51:50,927 - [test_login07.py -->line:52] - INFO:测试编号5,测试用例的标题为:用户名或密码错误,执行成功！
2021-06-21 16:51:51,005 - [test_regist07.py -->line:49] - INFO:测试编号1,测试用例标题正确流程,执行成功
2021-06-21 16:51:51,052 - [test_regist07.py -->line:49] - INFO:测试编号2,测试用例标题用户名为空,执行成功
2021-06-21 16:51:51,115 - [test_regist07.py -->line:49] - INFO:测试编号3,测试用例标题密码为空,执行成功
2021-06-21 16:51:51,162 - [test_regist07.py -->line:49] - INFO:测试编号4,测试用例标题确认密码不能为空,执行成功
2021-06-21 16:51:51,240 - [test_regist07.py -->line:49] - INFO:测试编号5,测试用例标题用户名已经存在,执行成功
2021-06-21 16:51:51,286 - [test_regist07.py -->line:49] - INFO:测试编号6,测试用例标题密码和确认密码不一致,执行成功
2021-06-21 16:51:51,333 - [test_regist07.py -->line:49] - INFO:测试编号7,测试用例标题用户名小于6位,执行成功
2021-06-21 16:51:51,396 - [test_regist07.py -->line:49] - INFO:测试编号8,测试用例标题用户名大于18位,执行成功
2021-06-21 16:51:51,443 - [test_regist07.py -->line:49] - INFO:测试编号9,测试用例标题密码小于6位,执行成功
2021-06-21 16:51:51,475 - [test_regist07.py -->line:49] - INFO:测试编号10,测试用例标题密码大于18位,执行成功
2021-06-21 16:51:51,506 - [test_regist07.py -->line:49] - INFO:测试编号11,测试用例标题密码17位,执行成功
2021-06-21 16:51:51,522 - [test_regist07.py -->line:44] - ERROR:测试编号12,测试用例标题邮箱不能为空,执行失败,实际结果：{'code': 1006, 'msg': '邮箱不能为空'}
2021-06-21 16:51:51,522 - [test_regist07.py -->line:45] - ERROR:{'code': 10066, 'msg': '邮箱不能为空'} != {'code': 1006, 'msg': '邮箱不能为空'}
- {'code': 10066, 'msg': '邮箱不能为空'}
?              -

+ {'code': 1006, 'msg': '邮箱不能为空'}
Traceback (most recent call last):
  File "D:\Tools\PythonWorkSpace\autotest02\testcases\test_regist07.py", line 40, in test_register
    self.assertEqual(eval(case.expect), res_body)
  File "D:\Tools\Python\lib\unittest\case.py", line 839, in assertEqual
    assertion_func(first, second, msg=msg)
  File "D:\Tools\Python\lib\unittest\case.py", line 1138, in assertDictEqual
    self.fail(self._formatMessage(msg, standardMsg))
  File "D:\Tools\Python\lib\unittest\case.py", line 680, in fail
    raise self.failureException(msg)
AssertionError: {'code': 10066, 'msg': '邮箱不能为空'} != {'code': 1006, 'msg': '邮箱不能为空'}
- {'code': 10066, 'msg': '邮箱不能为空'}
?              -

+ {'code': 1006, 'msg': '邮箱不能为空'}
2021-06-22 11:30:52,252 - [test_Login_Teacher.py -->line:51] - INFO:测试编号1,测试用例的标题为:登录成功,执行成功！
2021-06-22 11:30:52,280 - [test_Login_Teacher.py -->line:51] - INFO:测试编号2,测试用例的标题为:用户名为空,执行成功！
2021-06-22 11:30:52,306 - [test_Login_Teacher.py -->line:51] - INFO:测试编号3,测试用例的标题为:错误的用户名,执行成功！
2021-06-22 11:30:52,333 - [test_Login_Teacher.py -->line:46] - ERROR:测试编号4,测试用例的标题为:大小写区分,执行失败！实际结果为:{'code': 1000, 'msg': '登录成功', 'token': 'MTYyNDM2MjY1Mi4zMTA0NDAzOjYzNjMyN2I5NTMxMmM3NGMyNjdjYTYwZmQyNDM0NjQyM2FkNThjYWI='}
2021-06-22 11:30:52,334 - [test_Login_Teacher.py -->line:47] - ERROR:{'code': 1007, 'msg': '用户名或者密码错误'} != {'code': 1000, 'msg': '登录成功', 'token': 'MTYyNDM2MjY1M[64 chars]WI='}
- {'code': 1007, 'msg': '用户名或者密码错误'}
+ {'code': 1000,
+  'msg': '登录成功',
+  'token': 'MTYyNDM2MjY1Mi4zMTA0NDAzOjYzNjMyN2I5NTMxMmM3NGMyNjdjYTYwZmQyNDM0NjQyM2FkNThjYWI='}
Traceback (most recent call last):
  File "D:\Tools\PythonWorkSpace\autotest02\testcases\test_Login_Teacher.py", line 43, in test_login01
    self.assertEqual(eval(case.expect), res_body)
  File "D:\Tools\Python\lib\unittest\case.py", line 839, in assertEqual
    assertion_func(first, second, msg=msg)
  File "D:\Tools\Python\lib\unittest\case.py", line 1138, in assertDictEqual
    self.fail(self._formatMessage(msg, standardMsg))
  File "D:\Tools\Python\lib\unittest\case.py", line 680, in fail
    raise self.failureException(msg)
AssertionError: {'code': 1007, 'msg': '用户名或者密码错误'} != {'code': 1000, 'msg': '登录成功', 'token': 'MTYyNDM2MjY1M[64 chars]WI='}
- {'code': 1007, 'msg': '用户名或者密码错误'}
+ {'code': 1000,
+  'msg': '登录成功',
+  'token': 'MTYyNDM2MjY1Mi4zMTA0NDAzOjYzNjMyN2I5NTMxMmM3NGMyNjdjYTYwZmQyNDM0NjQyM2FkNThjYWI='}
2021-06-22 11:30:52,363 - [test_Login_Teacher.py -->line:51] - INFO:测试编号5,测试用例的标题为:密码为空,执行成功！
2021-06-22 11:30:52,393 - [test_Login_Teacher.py -->line:51] - INFO:测试编号6,测试用例的标题为:密码错误,执行成功！
2021-06-22 11:30:52,421 - [test_Login_Teacher.py -->line:46] - ERROR:测试编号7,测试用例的标题为:大小写区分,执行失败！实际结果为:{'code': 1000, 'msg': '登录成功', 'token': 'MTYyNDM2MjY1Mi4zOTcyMDc1OmJmYzYzMTNjOWY2YzliOWNlYTdiMDVkY2Q1ZjQzOTdkOTU4MjI1ODQ='}
2021-06-22 11:30:52,422 - [test_Login_Teacher.py -->line:47] - ERROR:{'code': 1007, 'msg': '用户名或者密码错误'} != {'code': 1000, 'msg': '登录成功', 'token': 'MTYyNDM2MjY1M[64 chars]DQ='}
- {'code': 1007, 'msg': '用户名或者密码错误'}
+ {'code': 1000,
+  'msg': '登录成功',
+  'token': 'MTYyNDM2MjY1Mi4zOTcyMDc1OmJmYzYzMTNjOWY2YzliOWNlYTdiMDVkY2Q1ZjQzOTdkOTU4MjI1ODQ='}
Traceback (most recent call last):
  File "D:\Tools\PythonWorkSpace\autotest02\testcases\test_Login_Teacher.py", line 43, in test_login01
    self.assertEqual(eval(case.expect), res_body)
  File "D:\Tools\Python\lib\unittest\case.py", line 839, in assertEqual
    assertion_func(first, second, msg=msg)
  File "D:\Tools\Python\lib\unittest\case.py", line 1138, in assertDictEqual
    self.fail(self._formatMessage(msg, standardMsg))
  File "D:\Tools\Python\lib\unittest\case.py", line 680, in fail
    raise self.failureException(msg)
AssertionError: {'code': 1007, 'msg': '用户名或者密码错误'} != {'code': 1000, 'msg': '登录成功', 'token': 'MTYyNDM2MjY1M[64 chars]DQ='}
- {'code': 1007, 'msg': '用户名或者密码错误'}
+ {'code': 1000,
+  'msg': '登录成功',
+  'token': 'MTYyNDM2MjY1Mi4zOTcyMDc1OmJmYzYzMTNjOWY2YzliOWNlYTdiMDVkY2Q1ZjQzOTdkOTU4MjI1ODQ='}
2021-06-22 11:30:52,450 - [test_Login_Teacher.py -->line:51] - INFO:测试编号8,测试用例的标题为:用户类型为空,执行成功！
2021-06-22 11:30:52,484 - [test_Login_Teacher.py -->line:51] - INFO:测试编号9,测试用例的标题为:用户类型非枚举,执行成功！
2021-06-22 11:30:52,525 - [test_Login_Teacher.py -->line:51] - INFO:测试编号10,测试用例的标题为:非普通用户,执行成功！
2021-06-22 11:30:52,570 - [test_Login_Teacher.py -->line:51] - INFO:测试编号11,测试用例的标题为:格式错误,执行成功！
2021-06-22 11:30:58,794 - [test_Login_Teacher.py -->line:51] - INFO:测试编号1,测试用例的标题为:登录成功,执行成功！
2021-06-22 11:30:58,821 - [test_Login_Teacher.py -->line:51] - INFO:测试编号2,测试用例的标题为:用户名为空,执行成功！
2021-06-22 11:30:58,850 - [test_Login_Teacher.py -->line:51] - INFO:测试编号3,测试用例的标题为:错误的用户名,执行成功！
2021-06-22 11:30:58,879 - [test_Login_Teacher.py -->line:46] - ERROR:测试编号4,测试用例的标题为:大小写区分,执行失败！实际结果为:{'code': 1000, 'msg': '登录成功', 'token': 'MTYyNDM2MjY1OC44NTU0NTgzOjFhYzJmNjliNGQ1Y2VkY2VmNTIxODQwZTUyZDYwM2Y0MmFmNTllYjg='}
2021-06-22 11:30:58,879 - [test_Login_Teacher.py -->line:47] - ERROR:{'code': 1007, 'msg': '用户名或者密码错误'} != {'code': 1000, 'msg': '登录成功', 'token': 'MTYyNDM2MjY1O[64 chars]jg='}
- {'code': 1007, 'msg': '用户名或者密码错误'}
+ {'code': 1000,
+  'msg': '登录成功',
+  'token': 'MTYyNDM2MjY1OC44NTU0NTgzOjFhYzJmNjliNGQ1Y2VkY2VmNTIxODQwZTUyZDYwM2Y0MmFmNTllYjg='}
Traceback (most recent call last):
  File "D:\Tools\PythonWorkSpace\autotest02\testcases\test_Login_Teacher.py", line 43, in test_login01
    self.assertEqual(eval(case.expect), res_body)
  File "D:\Tools\Python\lib\unittest\case.py", line 839, in assertEqual
    assertion_func(first, second, msg=msg)
  File "D:\Tools\Python\lib\unittest\case.py", line 1138, in assertDictEqual
    self.fail(self._formatMessage(msg, standardMsg))
  File "D:\Tools\Python\lib\unittest\case.py", line 680, in fail
    raise self.failureException(msg)
AssertionError: {'code': 1007, 'msg': '用户名或者密码错误'} != {'code': 1000, 'msg': '登录成功', 'token': 'MTYyNDM2MjY1O[64 chars]jg='}
- {'code': 1007, 'msg': '用户名或者密码错误'}
+ {'code': 1000,
+  'msg': '登录成功',
+  'token': 'MTYyNDM2MjY1OC44NTU0NTgzOjFhYzJmNjliNGQ1Y2VkY2VmNTIxODQwZTUyZDYwM2Y0MmFmNTllYjg='}
2021-06-22 11:30:58,906 - [test_Login_Teacher.py -->line:51] - INFO:测试编号5,测试用例的标题为:密码为空,执行成功！
2021-06-22 11:30:58,936 - [test_Login_Teacher.py -->line:51] - INFO:测试编号6,测试用例的标题为:密码错误,执行成功！
2021-06-22 11:30:58,972 - [test_Login_Teacher.py -->line:46] - ERROR:测试编号7,测试用例的标题为:大小写区分,执行失败！实际结果为:{'code': 1000, 'msg': '登录成功', 'token': 'MTYyNDM2MjY1OC45NDEyMjk6MWQyZDg1MzkzNWMyMjg5ZDcyZDU0YjNjZmJmYzliMjkwZDA1ZWEzNg=='}
2021-06-22 11:30:58,972 - [test_Login_Teacher.py -->line:47] - ERROR:{'code': 1007, 'msg': '用户名或者密码错误'} != {'code': 1000, 'msg': '登录成功', 'token': 'MTYyNDM2MjY1O[64 chars]g=='}
- {'code': 1007, 'msg': '用户名或者密码错误'}
+ {'code': 1000,
+  'msg': '登录成功',
+  'token': 'MTYyNDM2MjY1OC45NDEyMjk6MWQyZDg1MzkzNWMyMjg5ZDcyZDU0YjNjZmJmYzliMjkwZDA1ZWEzNg=='}
Traceback (most recent call last):
  File "D:\Tools\PythonWorkSpace\autotest02\testcases\test_Login_Teacher.py", line 43, in test_login01
    self.assertEqual(eval(case.expect), res_body)
  File "D:\Tools\Python\lib\unittest\case.py", line 839, in assertEqual
    assertion_func(first, second, msg=msg)
  File "D:\Tools\Python\lib\unittest\case.py", line 1138, in assertDictEqual
    self.fail(self._formatMessage(msg, standardMsg))
  File "D:\Tools\Python\lib\unittest\case.py", line 680, in fail
    raise self.failureException(msg)
AssertionError: {'code': 1007, 'msg': '用户名或者密码错误'} != {'code': 1000, 'msg': '登录成功', 'token': 'MTYyNDM2MjY1O[64 chars]g=='}
- {'code': 1007, 'msg': '用户名或者密码错误'}
+ {'code': 1000,
+  'msg': '登录成功',
+  'token': 'MTYyNDM2MjY1OC45NDEyMjk6MWQyZDg1MzkzNWMyMjg5ZDcyZDU0YjNjZmJmYzliMjkwZDA1ZWEzNg=='}
2021-06-22 11:30:59,004 - [test_Login_Teacher.py -->line:51] - INFO:测试编号8,测试用例的标题为:用户类型为空,执行成功！
2021-06-22 11:30:59,035 - [test_Login_Teacher.py -->line:51] - INFO:测试编号9,测试用例的标题为:用户类型非枚举,执行成功！
2021-06-22 11:30:59,072 - [test_Login_Teacher.py -->line:51] - INFO:测试编号10,测试用例的标题为:非普通用户,执行成功！
2021-06-22 11:30:59,109 - [test_Login_Teacher.py -->line:51] - INFO:测试编号11,测试用例的标题为:格式错误,执行成功！
2021-06-22 11:31:01,786 - [test_Login_Teacher.py -->line:51] - INFO:测试编号1,测试用例的标题为:登录成功,执行成功！
2021-06-22 11:31:01,814 - [test_Login_Teacher.py -->line:51] - INFO:测试编号2,测试用例的标题为:用户名为空,执行成功！
2021-06-22 11:31:01,842 - [test_Login_Teacher.py -->line:51] - INFO:测试编号3,测试用例的标题为:错误的用户名,执行成功！
2021-06-22 11:31:01,870 - [test_Login_Teacher.py -->line:46] - ERROR:测试编号4,测试用例的标题为:大小写区分,执行失败！实际结果为:{'code': 1000, 'msg': '登录成功', 'token': 'MTYyNDM2MjY2MS44NDU0NjUyOjg0MjRmZDhlMTc0MTBlZDI4NTIyODk3OTAwOWRjNzE1ZTJiY2EzZTc='}
2021-06-22 11:31:01,870 - [test_Login_Teacher.py -->line:47] - ERROR:{'code': 1007, 'msg': '用户名或者密码错误'} != {'code': 1000, 'msg': '登录成功', 'token': 'MTYyNDM2MjY2M[64 chars]Tc='}
- {'code': 1007, 'msg': '用户名或者密码错误'}
+ {'code': 1000,
+  'msg': '登录成功',
+  'token': 'MTYyNDM2MjY2MS44NDU0NjUyOjg0MjRmZDhlMTc0MTBlZDI4NTIyODk3OTAwOWRjNzE1ZTJiY2EzZTc='}
Traceback (most recent call last):
  File "D:\Tools\PythonWorkSpace\autotest02\testcases\test_Login_Teacher.py", line 43, in test_login01
    self.assertEqual(eval(case.expect), res_body)
  File "D:\Tools\Python\lib\unittest\case.py", line 839, in assertEqual
    assertion_func(first, second, msg=msg)
  File "D:\Tools\Python\lib\unittest\case.py", line 1138, in assertDictEqual
    self.fail(self._formatMessage(msg, standardMsg))
  File "D:\Tools\Python\lib\unittest\case.py", line 680, in fail
    raise self.failureException(msg)
AssertionError: {'code': 1007, 'msg': '用户名或者密码错误'} != {'code': 1000, 'msg': '登录成功', 'token': 'MTYyNDM2MjY2M[64 chars]Tc='}
- {'code': 1007, 'msg': '用户名或者密码错误'}
+ {'code': 1000,
+  'msg': '登录成功',
+  'token': 'MTYyNDM2MjY2MS44NDU0NjUyOjg0MjRmZDhlMTc0MTBlZDI4NTIyODk3OTAwOWRjNzE1ZTJiY2EzZTc='}
2021-06-22 11:31:28,376 - [test_Login_Teacher.py -->line:51] - INFO:测试编号1,测试用例的标题为:登录成功,执行成功！
2021-06-22 11:31:28,407 - [test_Login_Teacher.py -->line:51] - INFO:测试编号2,测试用例的标题为:用户名为空,执行成功！
2021-06-22 11:31:28,439 - [test_Login_Teacher.py -->line:51] - INFO:测试编号3,测试用例的标题为:错误的用户名,执行成功！
2021-06-22 11:31:28,469 - [test_Login_Teacher.py -->line:46] - ERROR:测试编号4,测试用例的标题为:大小写区分,执行失败！实际结果为:{'code': 1000, 'msg': '登录成功', 'token': 'MTYyNDM2MjY4OC40NDMzNjE6Y2UyNWJkODlmNGQzMTA3ZmJlMTg2NWM5Y2Q3YzRkODE1Yzk4NzRjYQ=='}
2021-06-22 11:31:28,469 - [test_Login_Teacher.py -->line:47] - ERROR: :: {'code': 1007, 'msg': '用户名或者密码错误'} != {'code': 1000,
 'msg': '登录成功',
 'token': 'MTYyNDM2MjY4OC40NDMzNjE6Y2UyNWJkODlmNGQzMTA3ZmJlMTg2NWM5Y2Q3YzRkODE1Yzk4NzRjYQ=='}
Traceback (most recent call last):
  File "D:\Tools\PyCharm Community Edition 2020.1.2\plugins\python-ce\helpers\pycharm\teamcity\diff_tools.py", line 32, in _patched_equals
    old(self, first, second, msg)
  File "D:\Tools\Python\lib\unittest\case.py", line 839, in assertEqual
    assertion_func(first, second, msg=msg)
  File "D:\Tools\Python\lib\unittest\case.py", line 1138, in assertDictEqual
    self.fail(self._formatMessage(msg, standardMsg))
  File "D:\Tools\Python\lib\unittest\case.py", line 680, in fail
    raise self.failureException(msg)
AssertionError: {'code': 1007, 'msg': '用户名或者密码错误'} != {'code': 1000, 'msg': '登录成功', 'token': 'MTYyNDM2MjY4O[64 chars]Q=='}
- {'code': 1007, 'msg': '用户名或者密码错误'}
+ {'code': 1000,
+  'msg': '登录成功',
+  'token': 'MTYyNDM2MjY4OC40NDMzNjE6Y2UyNWJkODlmNGQzMTA3ZmJlMTg2NWM5Y2Q3YzRkODE1Yzk4NzRjYQ=='}

During handling of the above exception, another exception occurred:

Traceback (most recent call last):
  File "D:\Tools\PythonWorkSpace\autotest02\testcases\test_Login_Teacher.py", line 43, in test_login01
    self.assertEqual(eval(case.expect), res_body)
  File "D:\Tools\PyCharm Community Edition 2020.1.2\plugins\python-ce\helpers\pycharm\teamcity\diff_tools.py", line 38, in _patched_equals
    raise error
teamcity.diff_tools.EqualsAssertionError:  :: {'code': 1007, 'msg': '用户名或者密码错误'} != {'code': 1000,
 'msg': '登录成功',
 'token': 'MTYyNDM2MjY4OC40NDMzNjE6Y2UyNWJkODlmNGQzMTA3ZmJlMTg2NWM5Y2Q3YzRkODE1Yzk4NzRjYQ=='}
2021-06-22 11:31:28,501 - [test_Login_Teacher.py -->line:51] - INFO:测试编号5,测试用例的标题为:密码为空,执行成功！
2021-06-22 11:31:28,529 - [test_Login_Teacher.py -->line:51] - INFO:测试编号6,测试用例的标题为:密码错误,执行成功！
2021-06-22 11:31:28,557 - [test_Login_Teacher.py -->line:46] - ERROR:测试编号7,测试用例的标题为:大小写区分,执行失败！实际结果为:{'code': 1000, 'msg': '登录成功', 'token': 'MTYyNDM2MjY4OC41MzMxMjE2OmJiMzViYjY2MmIzZjViNTE3MTJhYTkzNWNmZTRhYTJlODE0ZjJjMmY='}
2021-06-22 11:31:28,557 - [test_Login_Teacher.py -->line:47] - ERROR: :: {'code': 1007, 'msg': '用户名或者密码错误'} != {'code': 1000,
 'msg': '登录成功',
 'token': 'MTYyNDM2MjY4OC41MzMxMjE2OmJiMzViYjY2MmIzZjViNTE3MTJhYTkzNWNmZTRhYTJlODE0ZjJjMmY='}
Traceback (most recent call last):
  File "D:\Tools\PyCharm Community Edition 2020.1.2\plugins\python-ce\helpers\pycharm\teamcity\diff_tools.py", line 32, in _patched_equals
    old(self, first, second, msg)
  File "D:\Tools\Python\lib\unittest\case.py", line 839, in assertEqual
    assertion_func(first, second, msg=msg)
  File "D:\Tools\Python\lib\unittest\case.py", line 1138, in assertDictEqual
    self.fail(self._formatMessage(msg, standardMsg))
  File "D:\Tools\Python\lib\unittest\case.py", line 680, in fail
    raise self.failureException(msg)
AssertionError: {'code': 1007, 'msg': '用户名或者密码错误'} != {'code': 1000, 'msg': '登录成功', 'token': 'MTYyNDM2MjY4O[64 chars]mY='}
- {'code': 1007, 'msg': '用户名或者密码错误'}
+ {'code': 1000,
+  'msg': '登录成功',
+  'token': 'MTYyNDM2MjY4OC41MzMxMjE2OmJiMzViYjY2MmIzZjViNTE3MTJhYTkzNWNmZTRhYTJlODE0ZjJjMmY='}

During handling of the above exception, another exception occurred:

Traceback (most recent call last):
  File "D:\Tools\PythonWorkSpace\autotest02\testcases\test_Login_Teacher.py", line 43, in test_login01
    self.assertEqual(eval(case.expect), res_body)
  File "D:\Tools\PyCharm Community Edition 2020.1.2\plugins\python-ce\helpers\pycharm\teamcity\diff_tools.py", line 38, in _patched_equals
    raise error
teamcity.diff_tools.EqualsAssertionError:  :: {'code': 1007, 'msg': '用户名或者密码错误'} != {'code': 1000,
 'msg': '登录成功',
 'token': 'MTYyNDM2MjY4OC41MzMxMjE2OmJiMzViYjY2MmIzZjViNTE3MTJhYTkzNWNmZTRhYTJlODE0ZjJjMmY='}
2021-06-22 11:31:28,588 - [test_Login_Teacher.py -->line:51] - INFO:测试编号8,测试用例的标题为:用户类型为空,执行成功！
2021-06-22 11:31:28,622 - [test_Login_Teacher.py -->line:51] - INFO:测试编号9,测试用例的标题为:用户类型非枚举,执行成功！
2021-06-22 11:31:28,652 - [test_Login_Teacher.py -->line:51] - INFO:测试编号10,测试用例的标题为:非普通用户,执行成功！
2021-06-22 11:31:28,683 - [test_Login_Teacher.py -->line:51] - INFO:测试编号11,测试用例的标题为:格式错误,执行成功！
2021-06-22 11:38:17,120 - [test_Login_Teacher.py -->line:50] - INFO:测试编号1,测试用例的标题为:登录成功,执行成功！
2021-06-22 11:38:17,149 - [test_Login_Teacher.py -->line:50] - INFO:测试编号2,测试用例的标题为:用户名为空,执行成功！
2021-06-22 11:38:17,178 - [test_Login_Teacher.py -->line:50] - INFO:测试编号3,测试用例的标题为:错误的用户名,执行成功！
2021-06-22 11:38:17,209 - [test_Login_Teacher.py -->line:45] - ERROR:测试编号4,测试用例的标题为:大小写区分,执行失败！实际结果为:{'code': 1000, 'msg': '登录成功', 'token': 'MTYyNDM2MzA5Ny4xODMyNjMzOjJjMjhlYzkzOTU2ZDAxMzBiMjJhMDM0MTE0OTQ0YzYyMWU0OTVmZGY='}
2021-06-22 11:38:17,209 - [test_Login_Teacher.py -->line:46] - ERROR: :: {'code': 1007, 'msg': '用户名或者密码错误'} != {'code': 1000,
 'msg': '登录成功',
 'token': 'MTYyNDM2MzA5Ny4xODMyNjMzOjJjMjhlYzkzOTU2ZDAxMzBiMjJhMDM0MTE0OTQ0YzYyMWU0OTVmZGY='}
Traceback (most recent call last):
  File "D:\Tools\PyCharm Community Edition 2020.1.2\plugins\python-ce\helpers\pycharm\teamcity\diff_tools.py", line 32, in _patched_equals
    old(self, first, second, msg)
  File "D:\Tools\Python\lib\unittest\case.py", line 839, in assertEqual
    assertion_func(first, second, msg=msg)
  File "D:\Tools\Python\lib\unittest\case.py", line 1138, in assertDictEqual
    self.fail(self._formatMessage(msg, standardMsg))
  File "D:\Tools\Python\lib\unittest\case.py", line 680, in fail
    raise self.failureException(msg)
AssertionError: {'code': 1007, 'msg': '用户名或者密码错误'} != {'code': 1000, 'msg': '登录成功', 'token': 'MTYyNDM2MzA5N[64 chars]GY='}
- {'code': 1007, 'msg': '用户名或者密码错误'}
+ {'code': 1000,
+  'msg': '登录成功',
+  'token': 'MTYyNDM2MzA5Ny4xODMyNjMzOjJjMjhlYzkzOTU2ZDAxMzBiMjJhMDM0MTE0OTQ0YzYyMWU0OTVmZGY='}

During handling of the above exception, another exception occurred:

Traceback (most recent call last):
  File "D:\Tools\PythonWorkSpace\autotest02\testcases\test_Login_Teacher.py", line 42, in test_login01
    self.assertEqual(eval(case.expect), res_body)
  File "D:\Tools\PyCharm Community Edition 2020.1.2\plugins\python-ce\helpers\pycharm\teamcity\diff_tools.py", line 38, in _patched_equals
    raise error
teamcity.diff_tools.EqualsAssertionError:  :: {'code': 1007, 'msg': '用户名或者密码错误'} != {'code': 1000,
 'msg': '登录成功',
 'token': 'MTYyNDM2MzA5Ny4xODMyNjMzOjJjMjhlYzkzOTU2ZDAxMzBiMjJhMDM0MTE0OTQ0YzYyMWU0OTVmZGY='}
2021-06-22 11:38:17,240 - [test_Login_Teacher.py -->line:50] - INFO:测试编号5,测试用例的标题为:密码为空,执行成功！
2021-06-22 11:38:17,269 - [test_Login_Teacher.py -->line:50] - INFO:测试编号6,测试用例的标题为:密码错误,执行成功！
2021-06-22 11:38:17,299 - [test_Login_Teacher.py -->line:45] - ERROR:测试编号7,测试用例的标题为:大小写区分,执行失败！实际结果为:{'code': 1000, 'msg': '登录成功', 'token': 'MTYyNDM2MzA5Ny4yNzMwMjI3OjU2OWM3YTIxNWM5NmZhMzM5YjhmMTU5NTFmN2JhZDA1OGIyY2I2YWE='}
2021-06-22 11:38:17,299 - [test_Login_Teacher.py -->line:46] - ERROR: :: {'code': 1007, 'msg': '用户名或者密码错误'} != {'code': 1000,
 'msg': '登录成功',
 'token': 'MTYyNDM2MzA5Ny4yNzMwMjI3OjU2OWM3YTIxNWM5NmZhMzM5YjhmMTU5NTFmN2JhZDA1OGIyY2I2YWE='}
Traceback (most recent call last):
  File "D:\Tools\PyCharm Community Edition 2020.1.2\plugins\python-ce\helpers\pycharm\teamcity\diff_tools.py", line 32, in _patched_equals
    old(self, first, second, msg)
  File "D:\Tools\Python\lib\unittest\case.py", line 839, in assertEqual
    assertion_func(first, second, msg=msg)
  File "D:\Tools\Python\lib\unittest\case.py", line 1138, in assertDictEqual
    self.fail(self._formatMessage(msg, standardMsg))
  File "D:\Tools\Python\lib\unittest\case.py", line 680, in fail
    raise self.failureException(msg)
AssertionError: {'code': 1007, 'msg': '用户名或者密码错误'} != {'code': 1000, 'msg': '登录成功', 'token': 'MTYyNDM2MzA5N[64 chars]WE='}
- {'code': 1007, 'msg': '用户名或者密码错误'}
+ {'code': 1000,
+  'msg': '登录成功',
+  'token': 'MTYyNDM2MzA5Ny4yNzMwMjI3OjU2OWM3YTIxNWM5NmZhMzM5YjhmMTU5NTFmN2JhZDA1OGIyY2I2YWE='}

During handling of the above exception, another exception occurred:

Traceback (most recent call last):
  File "D:\Tools\PythonWorkSpace\autotest02\testcases\test_Login_Teacher.py", line 42, in test_login01
    self.assertEqual(eval(case.expect), res_body)
  File "D:\Tools\PyCharm Community Edition 2020.1.2\plugins\python-ce\helpers\pycharm\teamcity\diff_tools.py", line 38, in _patched_equals
    raise error
teamcity.diff_tools.EqualsAssertionError:  :: {'code': 1007, 'msg': '用户名或者密码错误'} != {'code': 1000,
 'msg': '登录成功',
 'token': 'MTYyNDM2MzA5Ny4yNzMwMjI3OjU2OWM3YTIxNWM5NmZhMzM5YjhmMTU5NTFmN2JhZDA1OGIyY2I2YWE='}
2021-06-22 11:38:17,329 - [test_Login_Teacher.py -->line:50] - INFO:测试编号8,测试用例的标题为:用户类型为空,执行成功！
2021-06-22 11:38:17,359 - [test_Login_Teacher.py -->line:50] - INFO:测试编号9,测试用例的标题为:用户类型非枚举,执行成功！
2021-06-22 11:38:17,390 - [test_Login_Teacher.py -->line:50] - INFO:测试编号10,测试用例的标题为:非普通用户,执行成功！
2021-06-22 11:38:17,420 - [test_Login_Teacher.py -->line:50] - INFO:测试编号11,测试用例的标题为:格式错误,执行成功！
2021-06-22 14:09:30,060 - [test_Login_Teacher.py -->line:50] - INFO:测试编号1,测试用例的标题为:登录成功,执行成功！
2021-06-22 14:09:30,090 - [test_Login_Teacher.py -->line:50] - INFO:测试编号2,测试用例的标题为:用户名为空,执行成功！
2021-06-22 14:09:30,118 - [test_Login_Teacher.py -->line:50] - INFO:测试编号3,测试用例的标题为:错误的用户名,执行成功！
2021-06-22 14:09:30,148 - [test_Login_Teacher.py -->line:45] - ERROR:测试编号4,测试用例的标题为:大小写区分,执行失败！实际结果为:{'code': 1000, 'msg': '登录成功', 'token': 'MTYyNDM3MjE3MC4xMjIyNjcyOmRkZGFkOWY5OGFlZTMxODdkZWJlZGIxNWRkMTY0MDI1OTY5NTk4OWY='}
2021-06-22 14:09:30,148 - [test_Login_Teacher.py -->line:46] - ERROR: :: {'code': 1007, 'msg': '用户名或者密码错误'} != {'code': 1000,
 'msg': '登录成功',
 'token': 'MTYyNDM3MjE3MC4xMjIyNjcyOmRkZGFkOWY5OGFlZTMxODdkZWJlZGIxNWRkMTY0MDI1OTY5NTk4OWY='}
Traceback (most recent call last):
  File "D:\Tools\PyCharm Community Edition 2020.1.2\plugins\python-ce\helpers\pycharm\teamcity\diff_tools.py", line 32, in _patched_equals
    old(self, first, second, msg)
  File "D:\Tools\Python\lib\unittest\case.py", line 839, in assertEqual
    assertion_func(first, second, msg=msg)
  File "D:\Tools\Python\lib\unittest\case.py", line 1138, in assertDictEqual
    self.fail(self._formatMessage(msg, standardMsg))
  File "D:\Tools\Python\lib\unittest\case.py", line 680, in fail
    raise self.failureException(msg)
AssertionError: {'code': 1007, 'msg': '用户名或者密码错误'} != {'code': 1000, 'msg': '登录成功', 'token': 'MTYyNDM3MjE3M[64 chars]WY='}
- {'code': 1007, 'msg': '用户名或者密码错误'}
+ {'code': 1000,
+  'msg': '登录成功',
+  'token': 'MTYyNDM3MjE3MC4xMjIyNjcyOmRkZGFkOWY5OGFlZTMxODdkZWJlZGIxNWRkMTY0MDI1OTY5NTk4OWY='}

During handling of the above exception, another exception occurred:

Traceback (most recent call last):
  File "D:\Tools\PythonWorkSpace\autotest02\testcases\test_Login_Teacher.py", line 42, in test_login01
    self.assertEqual(eval(case.expect), res_body)
  File "D:\Tools\PyCharm Community Edition 2020.1.2\plugins\python-ce\helpers\pycharm\teamcity\diff_tools.py", line 38, in _patched_equals
    raise error
teamcity.diff_tools.EqualsAssertionError:  :: {'code': 1007, 'msg': '用户名或者密码错误'} != {'code': 1000,
 'msg': '登录成功',
 'token': 'MTYyNDM3MjE3MC4xMjIyNjcyOmRkZGFkOWY5OGFlZTMxODdkZWJlZGIxNWRkMTY0MDI1OTY5NTk4OWY='}
2021-06-22 14:09:30,180 - [test_Login_Teacher.py -->line:50] - INFO:测试编号5,测试用例的标题为:密码为空,执行成功！
2021-06-22 14:09:30,209 - [test_Login_Teacher.py -->line:50] - INFO:测试编号6,测试用例的标题为:密码错误,执行成功！
2021-06-22 14:09:30,236 - [test_Login_Teacher.py -->line:45] - ERROR:测试编号7,测试用例的标题为:大小写区分,执行失败！实际结果为:{'code': 1000, 'msg': '登录成功', 'token': 'MTYyNDM3MjE3MC4yMTMwMjQ2OjhjNjdhNmVjNjRkMTc3MzkzYzMzZDNhMGJkNjllYWU5Nzg3NWZhOGM='}
2021-06-22 14:09:30,236 - [test_Login_Teacher.py -->line:46] - ERROR: :: {'code': 1007, 'msg': '用户名或者密码错误'} != {'code': 1000,
 'msg': '登录成功',
 'token': 'MTYyNDM3MjE3MC4yMTMwMjQ2OjhjNjdhNmVjNjRkMTc3MzkzYzMzZDNhMGJkNjllYWU5Nzg3NWZhOGM='}
Traceback (most recent call last):
  File "D:\Tools\PyCharm Community Edition 2020.1.2\plugins\python-ce\helpers\pycharm\teamcity\diff_tools.py", line 32, in _patched_equals
    old(self, first, second, msg)
  File "D:\Tools\Python\lib\unittest\case.py", line 839, in assertEqual
    assertion_func(first, second, msg=msg)
  File "D:\Tools\Python\lib\unittest\case.py", line 1138, in assertDictEqual
    self.fail(self._formatMessage(msg, standardMsg))
  File "D:\Tools\Python\lib\unittest\case.py", line 680, in fail
    raise self.failureException(msg)
AssertionError: {'code': 1007, 'msg': '用户名或者密码错误'} != {'code': 1000, 'msg': '登录成功', 'token': 'MTYyNDM3MjE3M[64 chars]GM='}
- {'code': 1007, 'msg': '用户名或者密码错误'}
+ {'code': 1000,
+  'msg': '登录成功',
+  'token': 'MTYyNDM3MjE3MC4yMTMwMjQ2OjhjNjdhNmVjNjRkMTc3MzkzYzMzZDNhMGJkNjllYWU5Nzg3NWZhOGM='}

During handling of the above exception, another exception occurred:

Traceback (most recent call last):
  File "D:\Tools\PythonWorkSpace\autotest02\testcases\test_Login_Teacher.py", line 42, in test_login01
    self.assertEqual(eval(case.expect), res_body)
  File "D:\Tools\PyCharm Community Edition 2020.1.2\plugins\python-ce\helpers\pycharm\teamcity\diff_tools.py", line 38, in _patched_equals
    raise error
teamcity.diff_tools.EqualsAssertionError:  :: {'code': 1007, 'msg': '用户名或者密码错误'} != {'code': 1000,
 'msg': '登录成功',
 'token': 'MTYyNDM3MjE3MC4yMTMwMjQ2OjhjNjdhNmVjNjRkMTc3MzkzYzMzZDNhMGJkNjllYWU5Nzg3NWZhOGM='}
2021-06-22 14:09:30,265 - [test_Login_Teacher.py -->line:50] - INFO:测试编号8,测试用例的标题为:用户类型为空,执行成功！
2021-06-22 14:09:30,294 - [test_Login_Teacher.py -->line:50] - INFO:测试编号9,测试用例的标题为:用户类型非枚举,执行成功！
2021-06-22 14:09:30,323 - [test_Login_Teacher.py -->line:50] - INFO:测试编号10,测试用例的标题为:非普通用户,执行成功！
2021-06-22 14:09:30,352 - [test_Login_Teacher.py -->line:50] - INFO:测试编号11,测试用例的标题为:格式错误,执行成功！
